Workbook
Name BloatingTable: 'Bloating(do not use)'!$B$1:$G$17
Name BloatingTable2: 'Bloating(do not use)'!$B$2:$H$17
Name BloatingTable3: 'Bloating(do not use)'!$A$2:$H$17

Sheet Health Concern
B2: Health Concern
B3: Bloating
B4: Colic (infants)
B5: Constipation
B6: Daiarrhoea
B7: Dyspepsia
B8: Flatulence
B9: Poor Appetite
B10: Poor Digestion

Sheet Reference sheet
A1: body_system | B1: health_concern | C1: herb_name | D1: latin_name | E1: actions | F1: indications | G1: energetics | H1: safety | I1: dose_min_ml | J1: dose_max_ml | K1: dose_unit | L1: ratio
A2: Digestion & Liver | B2: Bloating | C2: Angelica | D2: Angelica archangelica | E2: Carminative, Diaphoretic | F2: Dyspepsia | G2: Warm, Aromatic | H2: Avoid during pregnancy and lactation | I2: 4 | J2: 6 | K2: mL | L2: 1:2
A3: Digestion & Liver | B3: Bloating | C3: Aniseed | D3: Pimpinella anisum | E3: Carminative | F3: Colic (Infants), Dyspepsia | G3: Warm, Aromatic | H3: Use with caution in pregnancy | I3: 1 | J3: 4 | K3: mL | L3: 1:2
A4: Digestion & Liver | B4: Bloating | C4: Chamomile | D4: Matricaria chamomilla | E4: Carminative, Nervine | F4: Colic (Infants), Dyspepsia | G4: Neutral, Bitter, Nervine | H4: Allergic reactions possible | I4: 4 | J4: 10 | K4: mL | L4: 1:2
A5: Digestion & Liver | B5: Bloating | C5: Cinnamon | D5: Cinnamomum verum | E5: Carminative, Astringent | F5: Diarrhoea, Dyspepsia | G5: Hot, Aromatic | H5: Avoid high doses during pregnancy | I5: 2 | J5: 8 | K5: mL | L5: 1:2
A6: Digestion & Liver | B6: Bloating | C6: Dandelion Root | D6: Taraxacum officinale radix | E6: Cholagogue, Diuretic | F6: Constipation, Dyspepsia | G6: Cool, Bitter | H6: Avoid in cases of bile duct obstruction | I6: 4 | J6: 16 | K6: mL | L6: 1:2
A7: Digestion & Liver | B7: Bloating | C7: Fennel | D7: Foeniculum vulgare | E7: Carminative | F7: Colic (Infants), Dyspepsia | G7: Warm, Aromatic | H7: Use with caution in pregnancy | I7: 2 | J7: 4 | K7: mL | L7: 1:2
A8: Digestion & Liver | B8: Bloating | C8: Gentian | D8: Gentiana lutea | E8: Bitter Tonic | F8: Dyspepsia | G8: Cold, Bitter | H8: Avoid with gastric or duodenal ulcers | I8: 4 | J8: 8 | K8: mL | L8: 1:2
A9: Digestion & Liver | B9: Bloating | C9: Ginger | D9: Zingiber officinale | E9: Carminative, Diaphoretic | F9: Dyspepsia | G9: Hot, Aromatic | H9: Use with caution in pregnancy | I9: 4 | J9: 8 | K9: mL | L9: 1:2
A10: Digestion & Liver | B10: Bloating | C10: Globe Artichoke | D10: Cynara scolymus | E10: Cholagogue, Hepatic | F10: Dyspepsia | G10: Cool, Bitter | H10: Avoid in cases of bile duct obstruction | I10: 4 | J10: 16 | K10: mL | L10: 1:2
A11: Digestion & Liver | B11: Bloating | C11: Greater Celandine | D11: Chelidonium majus | E11: Cholagogue, Hepatic | F11: Dyspepsia | G11: Cold, Bitter | H11: High doses can be toxic | I11: 4 | J11: 16 | K11: mL | L11: 1:2
A12: Digestion & Liver | B12: Bloating | C12: Kawakawa | D12: Piper excelsum | E12: Carminative, Diaphoretic | F12: Diarrhoea, Dyspepsia | G12: Hot, Aromatic | H12: Safe for most individuals | I12: 4 | J12: 12 | K12: mL | L12: 1:2
A13: Digestion & Liver | B13: Bloating | C13: Kohekohe | D13: Dysoxylum spectabile | E13: Astringent | F13: Diarrhoea | G13: Cool, Astringent | H13: Not well-studied for safety | I13: 2 | J13: 4 | K13: mL | L13: 1:2
... A17: Digestion & Liver | B17: Bloating | C17: Sage | D17: Salvia officinalis | E17: Astringent, Antiseptic | F17: Dyspepsia | G17: Warm, Aromatic | H17: Avoid during pregnancy and lactation | I17: 2 | J17: 8 | K17: mL | L17: 1:2

Sheet Bloating(do not use)
B1: Herbs | C1: Actions | D1: Indications | E1: Energetic Properties | F1: Safety Precautions | G1: Therapeutic Dosage
B2: Angelica | C2: Carminative, Diaphoretic | D2: Dyspepsia | E2: Warm, Aromatic | F2: Avoid during pregnancy and lactation | G2: Infusion: 2-3g dried root
B3: Aniseed | C3: Carminative | D3: Colic (Infants), Dyspepsia | E3: Warm, Aromatic | F3: Use with caution in pregnancy | G3: Infusion: 0.5-2g crushed seeds
B4: Chamomile | C4: Carminative, Nervine | D4: Colic (Infants), Dyspepsia | E4: Neutral, Bitter, Nervine | F4: Allergic reactions possible | G4: Infusion: 2-5g dried flowers
B5: Cinnamon | C5: Carminative, Astringent | D5: Diarrhoea, Dyspepsia | E5: Hot, Aromatic | F5: Avoid high doses during pregnancy | G5: Infusion: 1-4g powdered bark
B6: Dandelion Root | C6: Cholagogue, Diuretic | D6: Constipation, Dyspepsia | E6: Cool, Bitter | F6: Avoid in cases of bile duct obstruction | G6: Decoction: 2-8g dried root
B7: Fennel | C7: Carminative | D7: Colic (Infants), Dyspepsia | E7: Warm, Aromatic | F7: Use with caution in pregnancy | G7: Infusion: 1-2g crushed seeds
B8: Gentian | C8: Bitter Tonic | D8: Dyspepsia | E8: Cold, Bitter | F8: Avoid with gastric or duodenal ulcers | G8: Infusion: 2-4g dried root
B9: Ginger | C9: Carminative, Diaphoretic | D9: Dyspepsia | E9: Hot, Aromatic | F9: Use with caution in pregnancy | G9: Infusion: 2-4g dried rhizome
B10: Globe Artichoke | C10: Cholagogue, Hepatic | D10: Dyspepsia | E10: Cool, Bitter | F10: Avoid in cases of bile duct obstruction | G10: Infusion: 2-8g dried leaf
B11: Greater Celandine | C11: Cholagogue, Hepatic | D11: Dyspepsia | E11: Cold, Bitter | F11: High doses can be toxic | G11: Infusion: 2-8g dried herb
B12: Kawakawa | C12: Carminative, Diaphoretic | D12: Diarrhoea, Dyspepsia | E12: Hot, Aromatic | F12: Safe for most individuals | G12: Infusion: 2-6g dried leaves
... B17: Sage | C17: Astringent, Antiseptic | D17: Dyspepsia | E17: Warm, Aromatic | F17: Avoid during pregnancy and lactation | G17: Infusion: 1-4g dried leaves

Sheet Cardiovascular (update WIP)
A1: body_system | B1: health_concern | C1: herb_name | D1: latin_name | E1: actions | F1: indications | G1: energetics | H1: safety | I1: dose_min_ml | J1: dose_max_ml | K1: dose_unit | L1: ratio
A2: Cardiovascular | B2: Angina | C2: Bitter Melon | D2: Momordica charantia | E2: Hypotensive, Anti-inflammatory | F2: Active compounds like charantin and polypeptide-P in bitter melon may influence factors involved in blood pressure regulation. This contributes to its hypotensive properties also due to reducing inflammation, which is often associated with heart health issues. | G2: Cooling, bitter | H2: Avoid during pregnancy, breastfeeding, if trying to conceive, glucose-6-phosphate dehydrogenase deficiency. | I2: 25 | J2: 40 | K2: mL | L2: 1:2
A3: Cardiovascular | B3: Angina | C3: Coleus | D3: Coleus forskohlii | E3: Cardiotonic | F3: Increase cyclic AMP levels, which may relax blood vessels and improve blood flow. This mechanism could potentially alleviate angina symptoms. | G3: Warming, Aromatic | H3: Contraindicated with hypotension and peptic ulcers | I3: 20 | J3: 40 | K3: mL | L3: 1:1
A4: Cardiovascular | B4: Angina | C4: Dan Shen | D4: Salvia miltiorrhiza | E4: Cardioprotective | F4: Contains tanshinones and salvianolic acids, these compounds may help improve blood flow and protect cardiovascular health, potentially aiding angina management. | G4: Cooling, Bitter | H4: Contraindicated in pregnancy,Contraindicated with anticoagulants | I4: 30 | J4: 60 | K4: mL | L4: 1:2
A5: Cardiovascular | B5: Angina | C5: Dong Quai | D5: Angelica sinensis | E5: Cardiotonic, Antiplatele, Antiplatelet | F5: Helps regulate blood pressure and improves circulation, these effects could potentially alleviate angina symptoms.. | G5: Warming, Aromatic | H5: Caution with heavy menstruation,Contraindicated during pregnancy | I5: 25 | J5: 50 | K5: mL | L5: 1:2
A6: Cardiovascular | B6: Angina | C6: Ginger | D6: Zingiber officinale | E6: Anti-inflammatory, Antiplatelet, Peripheral circulatory stimulant | F6: The compounds in ginger improves blood flow, potentially relieving chest pain associated with angina. | G6: Warming, Aromatic, Stimulating | H6: Caution with peptic ulcers, gallstones and during pregnancy | I6: 20 | J6: 50 | K6: mL | L6: 1:1
A7: Cardiovascular | B7: Angina | C7: Hawthorn | D7: Crataegus species | E7: Antiocidant, Cardioprotective, Cardiotonic, Hypotensive | F7: Flavonoids and procyanidins have vasodilatory effects, potentially improving blood flow to the heart. It may also support heart health by reducing oxidative stress and enhancing nitric oxide production. | G7: Neutral to slightly warming, Bitter | H7: N/A* | I7: 40 | J7: 80 | K7: mL | L7: 1:2
A8: Cardiovascular | B8: Angina | C8: Kudzu | D8: Pueraria lobata | E8: Anti-inflammatory, Hypolipidaemic | F8: Contains isoflavones that may enhance blood vessel dilation and improve blood flow which contribute to managing angina symptoms. | G8: Cooling, Sweet | H8: Avoid during pregnancy. CYP450 inhibitor may affect hepatic drug metabolism. | I8: 25 | J8: 50 | K8: mL | L8: 1:2
A9: Cardiovascular | B9: Angina | C9: Lime Flower | D9: Tilia species | E9: Peripheral vasodilator, Sedative (Relaxant) | F9: Promotes relaxation of blood vessels and reduces blood pressure influence heart health by modulating ion channels and enhancing blood vessel relaxation. | G9: Cooling, Aromatic | H9: ake away from iron supplements | I9: 30 | J9: 60 | K9: mL | L9: 1:2
A10: Cardiovascular | B10: Angina | C10: Mistletoe | D10: Viscum album | E10: Hypotensive, Sedative (Relaxant ) | F10: Improve blood flow and regulate heart rate may be due to its impact on autonomic nervous system activity. It could contribute to angina management by enhancing cardiovascular function. | G10: Neutral, Bitter | H10: N/A* | I10: 20 | J10: 40 | K10: mL | L10: 1:2
A11: Cardiovascular | B11: Angina | C11: Olive | D11: Olea europaea | E11: Antioxidant, Hypotensive | F11: Helps reduce inflammation and supports heart health which inturn support blood vessel health and alleviate angina symptoms. | G11: Neutral | H11: N/A* | I11: 40 | J11: 70 | K11: mL | L11: 1:2
A12: Cardiovascular | B12: Angina | C12: Saffron | D12: Crocus sativus | E12: Anti-inflammatory, Antioxidant, Hypolipidemic, Hypotensive | F12: Cardiovascular diseases Helps reduce chest pain and improves blood flow. Due to effects on endothelial function potentially aiding in angina management. | G12: Warming, Aromatic | H12: N/A* | I12: 5 | J12: 10 | K12: mL | L12: 1:2
A13: Cardiovascular | B13: Angina | C13: Tienchi | D13: Panax Ginseng | E13: Antiarrhythmic, Anti-inflammatory, Cardioprotective, Hypocholesterolaemic | F13: Enhance blood circulation and reduce blood clot formation may contribute to cardiovascular health. These effects could help manage angina symptoms. | G13: Neutral to slightly warming, Bitter | H13: Contraindicated in pregnancy,High doses may cause nervousness and sleeplessness | I13: 5 | J13: 15 | K13: mL | L13: 1:2
A14: Cardiovascular | B14: Angina | C14: Turmeric | D14: Curcuma longa | E14: Anti-inflammatory, Antioxidant, Antiplatelet, Hypolipidaemic | F14: Cardiovascular protection. Supports cardiovascular health and reduces inflammation. Support blood vessel health and cardiovascular function, potentially benefiting angina management. | G14: Warming, Bitter | H14: Possible potentiation of antiplatelet effect with high doses of turmeric or curcumin | I14: 40 | J14: 80 | K14: mL | L14: 1.1
A15: Cardiovascular | B15: Arrhythmia | C15: Corydalis | D15: Corydalis ambigua/yanhusuo | E15: Anti-arrhythmic, Sedative (Relaxant) | F15: Helps regulate heart rhythm and reduces arrhythmia symptoms by influencing cardiac ion channels and neurotransmitter systems. | G15: Warming, Bitter, Dispersing | H15: Contraindicated during pregnancy | I15: 20-60ml | J15: (1:2)
A16: Cardiovascular | B16: Arrhythmia | C16: Hawthorn | D16: Crataegus species | E16: Antioxidant, Cardioprotective, Cardiotonic hypotensive | F16: Flavonoids and procyanidins may enhance blood vessel dilation and improve blood flow, potentially supporting cardiac function and reducing arrhythmia. Its potential effects on ion channels could also contribute to helong irregular heart rhythms | G16: Neutral to slightly warming, Bitter | H16: N/A* | I16: )15-50 ml | J16: (1:2)
A17: Cardiovascular | B17: Arrhythmia | C17: Lime Flowers | D17: Tilia species | E17: Peripheral vasodilator, Sedative (Relaxant) | F17: Hypertension, Promotes relaxation and reduces heart palpitations. | G17: Cooling, Aromatic | H17: N/A* | I17: )15 - 40 mL | J17: (1:2)
A18: Cardiovascular | B18: Arrhythmia | C18: Motherwort | D18: Leonurus cardiaca | E18: Anti-arrhythmic, Cardiotonic | F18: Palpitations, Helps regulate heart rhythm and reduces arrhythmia symptoms | G18: Neutral to slightly cooling, Bitter | H18: Caution during pregnancy | I18: )15 - 30 mL | J18: (1:2)
A19: Cardiovascular | B19: Arrhythmia | C19: Tienchi | D19: Ginseng Panax | E19: Antiarrhythmic, Anti-inflammatory, Cardioprotective, Hypocholesterolaemic | F19: Enhance blood circulation and reduce blood clot formation may contribute to cardiovascular health. Its effects on blood flow and circulation | G19: Neutral to slightly warming, Bitter | H19: Contraindicated in pregnancy,High doses may cause nervousness and sleeplessness

Sheet Cardiovascular
C1: Herbs | E1: Actions | F1: indication | G1: Energetic Proties | H1: Safety precaution | I1: Therapeutic Dosage | J1: ratio
B2: ANGINA
A3: Cardiovascular | B3: Angina | C3: Bitter Melon | D3: Momordica charantia | E3: Hypotensive,Anti-inflammatory | F3: Active compounds like charantin and polypeptide-P in bitter melon may influence factors involved in blood pressure regulation, contributing to its hypotensive properties also due to reducing inflammation, which is often associated with heart health issues. | G3: Cooling, bitter | H3: Avoid during pregnancy, breastfeeding, if trying to conceive, glucose-6-phosphate dehydrogenase deficiency. | I3: 30-60 ml | J3: (1:2)
A4: Cardiovascular | B4: Angina | C4: Coleus | D4: Coleus forskohlii | E4: Cardiotonic | F4: increase cyclic AMP levels, which may relax blood vessels and improve blood flow. This mechanism could potentially alleviate angina symptoms. | G4: Warming, Aromatic | H4: Contraindicated with hypotension and peptic ulcers | I4: 40-90 ml | J4: 1.1
A5: Cardiovascular | B5: Angina | C5: Dan Shen | D5: Salvia miltiorrhiza | E5: Cardioprotective | F5: contains tanshinones and salvianolic acids . These compounds may help improve blood flow and protect cardiovascular health, potentially aiding angina management. | G5: Cooling, Bitter | H5: Contraindicated in pregnancy,Contraindicated with anticoagulants | I5: 20-80 ml
A6: Cardiovascular | B6: Angina | C6: Dong Quai | D6: Angelica sinensis | E6: cardiotonic,Antiplatele,Antiplatelet | F6: Helps regulate blood pressure and improves circulation These effects could potentially alleviate angina symptoms.. | G6: Warming, Aromatic | H6: Caution with heavy menstruation,Contraindicated during pregnancy | I6: 30-60 ml | J6: (1:2)
A7: Cardiovascular | B7: Angina | C7: Ginger | D7: Zingiber officinale | E7: Anti-inflammatory,Antiplatelet,Peripheral circulatory stimulant | F7: The compounds in ginger -gingerols improve blood flow, potentially relieving chest pain associated with angina. | G7: Warming, Aromatic, Stimulating | H7: Caution with peptic ulcers, gallstones and during pregnancy | I7: 5-15ml | J7: 1.5
A8: Cardiovascular | B8: Angina | C8: Hawthorn | D8: Crataegus species | E8: Antiocidant,Cardioprotective,cardiotonic,hypotensive | F8: flavonoids and procyanidins have vasodilatory effects, potentially improving blood flow to the heart. It may also support heart health by reducing oxidative stress and enhancing nitric oxide production. | G8: Neutral to slightly warming, Bitter | H8: N/A* | I8: 15-50 ml | J8: (1:2)
A9: Cardiovascular | B9: Angina | C9: Kudzu | D9: Pueraria lobata | E9: Anti-inflammatory, hypolipidaemic | F9: contains isoflavones that may enhance blood vessel dilation and improve blood flow which contribute to managing angina symptoms. | G9: Cooling, Sweet | H9: Avoid during pregnancy. CYP450 inhibitor may affect hepatic drug metabolism. | I9: 25 - 70 mL | J9: (1:2)
A10: Cardiovascular | B10: Angina | C10: Lime Flower | D10: Tilia species | E10: Peripheral vasodilator,Sedative/relaxant | F10: Angina, Arrhythmia, Hypertension, Palpitations Promotes relaxation of blood vessels and reduces blood pressure influence heart health by modulating ion channels and enhancing blood vessel relaxation. | G10: Cooling, Aromatic | H10: ake away from iron supplements | I10: )15 - 40 mL | J10: (1:2)
A11: Cardiovascular | B11: Angina | C11: Mistletoe | D11: Viscum album | E11: hypotensive, sedative/relaxant | F11: mprove blood flow and regulate heart rate may be due to its impact on autonomic nervous system activity. It could contribute to angina management by enhancing cardiovascular function. | G11: Neutral, Bitter | H11: N/A* | I11: 20 - 40 mL | J11: (1:2)
A12: Cardiovascular | B12: Angina | C12: Olive | D12: Olea europaea | E12: antioxidant,hypotensive | F12: Angina,Hypertension - Helps reduce inflammation and supports heart health which inturn support blood vessel health and alleviate angina symptoms. | G12: Neutral | H12: N/A* | I12: 25 - 50 mL | J12: (1:2)
A13: Cardiovascular | B13: Angina | C13: Saffron | D13: Crocus sativus | E13: Anti-inflammatory,Antioxidant,Hypolipidemic,Hypotensive | F13: Cardiovascular diseases Helps reduce chest pain and improves blood flow.due to effects on endothelial function potentially aiding in angina management. | G13: Warming, Aromatic | H13: N/A* | I13: 10 - 25 mL | J13: (1:2)
A14: Cardiovascular | B14: Angina | C14: Tienchi Ginseng Panax notoginseng | E14: Antiarrhythmic,Anti-inflammatory,Cardioprotective,Hypocholesterolaemic | F14: Angina,Arrhymia,Hypocholesterolaemia nhance blood circulation and reduce blood clot formation may contribute to cardiovascular health. These effects could help manage angina symptoms. | G14: Neutral to slightly warming, Bitter | H14: Contraindicated in pregnancy,High doses may cause nervousness and sleeplessness | I14: : 30 - 60 mL | J14: (1:2)
A15: Cardiovascular | B15: Angina | C15: Turmeric | D15: Curcuma longa | E15: Anti-inflammatory,Antioxidant,Antiplatelet,Hypolipidaemic | F15: Cardiovascular protection ,Supports cardiovascular health and reduces inflammation. support blood vessel health and cardiovascular function, potentially benefiting angina management. | G15: Warming, Bitter | H15: Possible potentiation of antiplatelet effect with high doses of turmeric or curcumin | I15: 35 - 90 mL | J15: 1.1
A16: Cardiovascular | B16: Arrhythmia | C16: Corydalis | D16: Corydalis ambigua/yanhusuo | E16: Anti-arrhythmic,Sedative/relaxant | F16: Arrhythmia / Palpitations , Helps regulate heart rhythm and reduces arrhythmia symptoms by influencing cardiac ion channels and neurotransmitter systems. | G16: Warming, Bitter, Dispersing | H16: Contraindicated during pregnancy | I16: 20-60ml | J16: (1:2)
A17: Cardiovascular | B17: Arrhythmia | C17: Hawthorn | D17: Crataegus species | E17: antioxidant,cardioprotective,cardiotonic hypotensive | F17: flavonoids and procyanidins may enhance blood vessel dilation and improve blood flow, potentially supporting cardiac function and reducing arrhythmia. Its potential effects on ion channels could also contribute to helong irregular heart rhythms | G17: Neutral to slightly warming, Bitter | H17: N/A* | I17: )15-50 ml | J17: (1:2)
A18: Cardiovascular | B18: Arrhythmia | C18: Lime Flowers | D18: Tilia species | E18: Peripheral vasodilator,Sedative/relaxant | F18: Angina, Arrhythmia, Hypertension, Palpitations,Promotes relaxation and reduces heart palpitations. | G18: Cooling, Aromatic | H18: N/A* | I18: )15 - 40 mL | J18: (1:2)
A19: Cardiovascular | B19: Arrhythmia | C19: Motherwort | D19: Leonurus cardiaca | E19: Anti-arrhythmic,Cardiotonic | F19: Arrhythmia, Palpitations, Helps regulate heart rhythm and reduces arrhythmia symptoms | G19: Neutral to slightly cooling, Bitter | H19: Caution during pregnancy | I19: )15 - 30 mL | J19: (1:2)
A20: Cardiovascular | B20: Arrhythmia | C20: Tienchi | D20: Ginseng Panax | E20: Antiarrhythmic,Anti-inflammatory,Cardioprotective,Hypocholesterolaemic | F20: enhance blood circulation and reduce blood clot formation may contribute to cardiovascular health. Its effects on blood flow and circulation | G20: Neutral to slightly warming, Bitter | H20: Contraindicated in pregnancy,High doses may cause nervousness and sleeplessness
A21: Cardiovascular | B21: Capillary fragility | C21: Bilberry | D21: Vaccinium myrtillus | E21: Anti-inflmmatory,Antioxidant,Antioedema,Astringent,Vasoprotective | F21: Haemorrhoids,vericose veins ,brusing,capillary fragility contains anthocyanins that may strengthen capillaries and improve microcirculation. Its potential antioxidant effects could also contribute to capillary health by reducing oxidative stress. | G21: Cooling, Aromatic | H21: N/A* | I21: 20-40 ml | J21: 1.1
A22: Cardiovascular | B22: Capillary fragility | C22: Butchers Broom | D22: Ruscus aculeatus | E22: Anti inflmmatory,Venous Tonic | F22: Haemorrhoids,vericose veins ,brusing,capillary fragility ,Supports supporting blood vessel tone and reducing capillary fragility. It may also help reduce inflammation and improve circulation. | G22: Cooling, Bitter | H22: Caution with GORD (saponins may aggravate) | I22: (1:2) 25-50 ml | J22: (1:2)
A23: Cardiovascular | B23: Capillary fragility | C23: Ginkgo | D23: Ginkgo biloba | E23: Antioxidant,Cardiotonic,Circulatory Stimulant, | F23: Poor circulation, varicose veins, capillary fragility,flavonoids and terpenoids may improve blood flow, enhancing oxygen and nutrient delivery to tissues. This could potentially strengthen capillaries and reduce their fragility. | G23: Cooling, Aromatic | H23: N/A* | I23: (3:2) 30-60 ml | J23: 3.2
A24: Cardiovascular | B24: Capillary fragility | C24: Gotu Kola | D24: Centella asiatica | E24: Anti-inflammatory,Venous tonic | F24: Varicose veins, capillary fragility, haemorrhoids, bruisincontains triterpenoids that may support connective tissue health and collagen production. This could contribute to strengthening capillaries and reducing their susceptibility to damage. | G24: Cooling, Bitter | H24: N/A* | I24: (1:2) 20-40 ml | J24: (1:2)
A25: Cardiovascular | B25: Capillary fragility | C25: Horse Chestnut | D25: Aesculus hippocastanum | E25: Anti-inflammatory,Venous tonic | F25: Varicose veins, capillary fragility, haemorrhoids, bruising has been shown to improve capillary wall integrity by reducing inflammation and enhancing blood flow. It may also have vasoconstrictive effects that support vein health. | G25: Cooling, Bitter | H25: Caution with GORD (saponins can aggravate) Do not apply directly to broken skin,Caution with GORD ( (saponins can aggravate) | I25: (1:2) 15-40ml | J25: (1:2)
A26: Cardiovascular | B26: Circulation / Raynaud's Syndrome | C26: Cayenne | D26: Capsicum annuum | E26: Circulatory stimulant | F26: Poor circulation,Raynaud's,contains capsaicin that may enhance blood flow by dilating blood vessels and improving circulation. Its warming effects could also support peripheral circulation and alleviate symptoms of Raynaud's syndrome. | G26: Warming, Stimulating | H26: Caution with peptic ulcers and GORD | I26: (1:3)1-4 ml | J26: 1.3
A27: Cardiovascular | B27: Circulation / Raynaud's Syndrome | C27: Crampbark | D27: Viburnum opulus | E27: Cardioprotective,Anticoagulant,Peripheral vasodilator | F27: Supports blood circulation and reduces symptoms of Raynaud's Syndrome improved blood flow and circulation. It may also help relax smooth muscles, potentially supporting overall vascular health. | G27: Cooling, Astringent | H27: N/A* | I27: (1:2)5-30 ml | J27: (1:2)
A28: Cardiovascular | B28: Circulation / Raynaud's Syndrome | C28: Dan Shen | D28: Salvia miltiorrhiza | E28: Cardioprotective | F28: upport blood vessel health by reducing oxidative stress and inflammation. These effects could potentially improve circulation and alleviate symptoms of Raynaud's syndrome. | G28: Cooling, Bitter | H28: Contraindicated in pregnancy,Contraindicated with anticoagulants | I28: (1:2) 20-80 ml | J28: (1:2)
A29: Cardiovascular | B29: Circulation / Raynaud's Syndrome | C29: Dong Quai | D29: Angelica sinensis | E29: cardiotonic,Antiplatele,Antiplatelet | F29: improve blood flow and support vascular health. These properties could potentially help manage symptoms of Raynaud's syndrome. | G29: Warming, Aromatic | H29: Caution with heavy menstruation,Contraindicated during pregnancy | I29: (1:2) 30-60 ml | J29: (1:2)
A30: Cardiovascular | B30: Circulation / Raynaud's Syndrome | C30: Garlic | D30: Allium sativum | E30: antioxidant,cardiotonic,hypocholesterolaemic | F30: Hypertension,Hypercholesterolaemia , allicin and other sulfur compounds have potential vasodilatory effects that could improve blood circulation. Its ability to enhance nitric oxide production may contribute to improved vascular function. | G30: Warming, Stimulating, Dispersing | H30: N/A* | I30: (1:1)30-100mls | J30: 1.1
A31: Cardiovascular | B31: Circulation / Raynaud's Syndrome | C31: Ginger | D31: Zingiber officinale | E31: Anti-inflammatory,Antiplatelet,Peripheral circulatory stimulant | F31: gingerols have vasodilatory and anti-inflammatory effects that could enhance blood flow and circulation. Its warming properties may also alleviate symptoms associated with Raynaud's syndrome. | G31: Warming, Aromatic, Stimulating | H31: Caution with peptic ulcers, gallstones and during pregnancy | I31: (1:2)5-15 ml | J31: (1:2)
A32: Cardiovascular | B32: Circulation / Raynaud's Syndrome | C32: Ginkgo | D32: Ginkgo biloba | E32: Antioxidant,cardiotonic,Circulatory stimulant | F32: lavonoids and terpenoids improve blood flow by dilating blood vessels and enhancing oxygen delivery. Its potential antioxidant effects could also protect blood vessels and support vascular health. | G32: Cooling, Aromatic | H32: N/A* | I32: (3:2) 30-60 ml | J32: 3.2
A33: Cardiovascular | B33: Circulation / Raynaud's Syndrome | C33: Hawthorn | D33: Crataegus species | E33: Antioxidant,Cardioprotective,cardiotonic,hypotensive | F33: flavonoids and procyanidins enhance blood vessel dilation and improve circulation. Its potential effects on blood pressure and cardiac function may also contribute to improved vascular health. | G33: Neutral to slightly warming, Bitter | H33: N/A* | I33: (1:2) 15-50ml | J33: (1:2)
A34: Cardiovascular | B34: Circulation / Raynaud's Syndrome | C34: Horopito | D34: Pseudowintera colorata | E34: Anti-inflammatory, circulatory stimulant | F34: Circulatory insufficiency, Raynaud's syndrome,improving blood flow and circulation. Its potential to improve blood vessel function could contribute to managing Raynaud's syndrome. | G34: Warming, Stimulating | H34: Avoid large doses with acute gastritis or peptic ulcers,Caution in pregnancy due to lack of evidence | I34: (1:2)10-30ml | J34: (1:2)
A35: Cardiovascular | B35: Circulation / Raynaud's Syndrome | C35: Kawakawa | D35: Macropiper excelsum | E35: Anti-inflammatory,Circulatory stimulant | F35: contains polyphenols that may support blood vessel health and improve circulation. Its potential anti-inflammatory effects could also alleviate symptoms of Raynaud's syndrome. | G35: Warming, Stimulating | H35: Caution in pregnancy due to lack of evidence | I35: (1:2) 20-60 mls | J35: (1:2)
A36: Cardiovascular | B36: Circulation / Raynaud's Syndrome | C36: Prickly Ash | D36: Zanthoxylum clava-herculis | E36: Antirheumatic,Circulatory stimulant | F36: Hypotenstion,poor circulation,Varicose Veins,Haemorrhoids stimulate blood flow and improve circulation may be attributed to its constituents like alkaloids. Its warming effects could also support peripheral circulation. | G36: Warming, Stimulating, Dispersing | H36: N/A* | I36: (1:2) 10-30 ml | J36: (1:2)
A37: Cardiovascular | B37: Heart Failure | C37: Dan Shen | D37: Salvia miltiorrhiza | E37: Cardioprotective | F37: Supports cardiovascular function helps improve blood circulation, reduce oxidative stress, and support heart health by enhancing blood vessel function. | G37: Cooling, Bitter | H37: Contraindicated in pregnancy,Contraindicated with anticoagulants | I37: (1:2) 20-80 ml | J37: (1:2)
A38: Cardiovascular | B38: Heart Failure | C38: Garlic | D38: Allium sativum | E38: antioxidant,cardiotonic,hypocholesterolaemic | F38: llicin and other sulfur compounds have potential vasodilatory effects that may improve blood flow and reduce blood pressure. Its antioxidant properties could also contribute to heart health by reducing oxidative stress. | G38: Warming, Stimulating, Dispersing | H38: N/A* | I38: (1:2) 20-80 ml | J38: (1:2)
A39: Cardiovascular | B39: Heart Failure | C39: Hawthorn | D39: Crataegus species | E39: Antiocidant,Cardioprotective,cardiotonic,hypotensive | F39: flavonoids and procyanidins may enhance blood vessel dilation and improve circulation. Its potential effects on cardiac contractility and blood pressure could support heart function and alleviate symptoms of heart failure. | G39: Neutral to slightly warming, Bitter | H39: N/A* | I39: (1:2)15-50 ml | J39: (1:2)
A40: Cardiovascular | B40: Heart Failure | C40: White Horehound | D40: Marrubium vulgare | E40: Cardiotonic | F40: Cardiovascular conditions, Heart failure contains compounds like marrubiin that may have potential vasodilatory and cardiotonic effects. These properties could contribute to improving blood flow and cardiac function in cases of heart failure. | G40: Cooling, Bitter | H40: N/A*
...

Sheet Digestion & Liver
B2: Select Health Concern: | C2: Bloating
B4: Herbs | C4: Actions | D4: Indications | E4: Energetic Properties | F4: Safety Precautions | G4: Therapeutic Dosage
B5: =OFFSET(BloatingTable2,MATCH('Health Concern'!$B$3,'Digestion & Liver'!$C$2,0)-1,0,1,COLUMNS(BloatingTable2)) -> Angelica | C5: =OFFSET(BloatingTable2,MATCH('Health Concern'!$B$3,'Digestion & Liver'!$C$2,0)-1,0,1,COLUMNS(BloatingTable2)) -> Carminative, Diaphoretic | D5: =OFFSET(BloatingTable2,MATCH('Health Concern'!$B$3,'Digestion & Liver'!$C$2,0)-1,0,1,COLUMNS(BloatingTable2)) -> Dyspepsia | E5: =OFFSET(BloatingTable2,MATCH('Health Concern'!$B$3,'Digestion & Liver'!$C$2,0)-1,0,1,COLUMNS(BloatingTable2)) -> Warm, Aromatic | F5: =OFFSET(BloatingTable2,MATCH('Health Concern'!$B$3,'Digestion & Liver'!$C$2,0)-1,0,1,COLUMNS(BloatingTable2)) -> Avoid during pregnancy and lactation | G5: =OFFSET(BloatingTable2,MATCH('Health Concern'!$B$3,'Digestion & Liver'!$C$2,0)-1,0,1,COLUMNS(BloatingTable2)) -> Infusion: 2-3g dried root
B6: =OFFSET(BloatingTable2,MATCH('Health Concern'!$B$3,'Digestion & Liver'!$C$2,0), 0,1,COLUMNS(BloatingTable2)) -> Aniseed | C6: =OFFSET(BloatingTable2,MATCH('Health Concern'!$B$3,'Digestion & Liver'!$C$2,0), 0,1,COLUMNS(BloatingTable2)) -> Carminative | D6: =OFFSET(BloatingTable2,MATCH('Health Concern'!$B$3,'Digestion & Liver'!$C$2,0), 0,1,COLUMNS(BloatingTable2)) -> Colic (Infants), Dyspepsia | E6: =OFFSET(BloatingTable2,MATCH('Health Concern'!$B$3,'Digestion & Liver'!$C$2,0), 0,1,COLUMNS(BloatingTable2)) -> Warm, Aromatic | F6: =OFFSET(BloatingTable2,MATCH('Health Concern'!$B$3,'Digestion & Liver'!$C$2,0), 0,1,COLUMNS(BloatingTable2)) -> Use with caution in pregnancy | G6: =OFFSET(BloatingTable2,MATCH('Health Concern'!$B$3,'Digestion & Liver'!$C$2,0), 0,1,COLUMNS(BloatingTable2)) -> Infusion: 0.5-2g crushed seeds
B7: =OFFSET(BloatingTable2,MATCH('Health Concern'!$B$3,'Digestion & Liver'!$C$2,0)+1, 0,1,COLUMNS(BloatingTable2)) -> Chamomile | C7: =OFFSET(BloatingTable2,MATCH('Health Concern'!$B$3,'Digestion & Liver'!$C$2,0)+1, 0,1,COLUMNS(BloatingTable2)) -> Carminative, Nervine | D7: =OFFSET(BloatingTable2,MATCH('Health Concern'!$B$3,'Digestion & Liver'!$C$2,0)+1, 0,1,COLUMNS(BloatingTable2)) -> Colic (Infants), Dyspepsia | E7: =OFFSET(BloatingTable2,MATCH('Health Concern'!$B$3,'Digestion & Liver'!$C$2,0)+1, 0,1,COLUMNS(BloatingTable2)) -> Neutral, Bitter, Nervine | F7: =OFFSET(BloatingTable2,MATCH('Health Concern'!$B$3,'Digestion & Liver'!$C$2,0)+1, 0,1,COLUMNS(BloatingTable2)) -> Allergic reactions possible | G7: =OFFSET(BloatingTable2,MATCH('Health Concern'!$B$3,'Digestion & Liver'!$C$2,0)+1, 0,1,COLUMNS(BloatingTable2)) -> Infusion: 2-5g dried flowers
B8: =OFFSET(BloatingTable2,MATCH('Health Concern'!$B$3,'Digestion & Liver'!$C$2,0)+2, 0,1,COLUMNS(BloatingTable2)) -> Cinnamon | C8: =OFFSET(BloatingTable2,MATCH('Health Concern'!$B$3,'Digestion & Liver'!$C$2,0)+2, 0,1,COLUMNS(BloatingTable2)) -> Carminative, Astringent | D8: =OFFSET(BloatingTable2,MATCH('Health Concern'!$B$3,'Digestion & Liver'!$C$2,0)+2, 0,1,COLUMNS(BloatingTable2)) -> Diarrhoea, Dyspepsia | E8: =OFFSET(BloatingTable2,MATCH('Health Concern'!$B$3,'Digestion & Liver'!$C$2,0)+2, 0,1,COLUMNS(BloatingTable2)) -> Hot, Aromatic | F8: =OFFSET(BloatingTable2,MATCH('Health Concern'!$B$3,'Digestion & Liver'!$C$2,0)+2, 0,1,COLUMNS(BloatingTable2)) -> Avoid high doses during pregnancy | G8: =OFFSET(BloatingTable2,MATCH('Health Concern'!$B$3,'Digestion & Liver'!$C$2,0)+2, 0,1,COLUMNS(BloatingTable2)) -> Infusion: 1-4g powdered bark
B9: =OFFSET(BloatingTable2,MATCH('Health Concern'!$B$3,'Digestion & Liver'!$C$2,0)+3, 0,1,COLUMNS(BloatingTable2)) -> Dandelion Root | C9: =OFFSET(BloatingTable2,MATCH('Health Concern'!$B$3,'Digestion & Liver'!$C$2,0)+3, 0,1,COLUMNS(BloatingTable2)) -> Cholagogue, Diuretic | D9: =OFFSET(BloatingTable2,MATCH('Health Concern'!$B$3,'Digestion & Liver'!$C$2,0)+3, 0,1,COLUMNS(BloatingTable2)) -> Constipation, Dyspepsia | E9: =OFFSET(BloatingTable2,MATCH('Health Concern'!$B$3,'Digestion & Liver'!$C$2,0)+3, 0,1,COLUMNS(BloatingTable2)) -> Cool, Bitter | F9: =OFFSET(BloatingTable2,MATCH('Health Concern'!$B$3,'Digestion & Liver'!$C$2,0)+3, 0,1,COLUMNS(BloatingTable2)) -> Avoid in cases of bile duct obstruction | G9: =OFFSET(BloatingTable2,MATCH('Health Concern'!$B$3,'Digestion & Liver'!$C$2,0)+3, 0,1,COLUMNS(BloatingTable2)) -> Decoction: 2-8g dried root
B10: =OFFSET(BloatingTable2,MATCH('Health Concern'!$B$3,'Digestion & Liver'!$C$2,0)+4, 0,1,COLUMNS(BloatingTable2)) -> Fennel | C10: =OFFSET(BloatingTable2,MATCH('Health Concern'!$B$3,'Digestion & Liver'!$C$2,0)+4, 0,1,COLUMNS(BloatingTable2)) -> Carminative | D10: =OFFSET(BloatingTable2,MATCH('Health Concern'!$B$3,'Digestion & Liver'!$C$2,0)+4, 0,1,COLUMNS(BloatingTable2)) -> Colic (Infants), Dyspepsia | E10: =OFFSET(BloatingTable2,MATCH('Health Concern'!$B$3,'Digestion & Liver'!$C$2,0)+4, 0,1,COLUMNS(BloatingTable2)) -> Warm, Aromatic | F10: =OFFSET(BloatingTable2,MATCH('Health Concern'!$B$3,'Digestion & Liver'!$C$2,0)+4, 0,1,COLUMNS(BloatingTable2)) -> Use with caution in pregnancy | G10: =OFFSET(BloatingTable2,MATCH('Health Concern'!$B$3,'Digestion & Liver'!$C$2,0)+4, 0,1,COLUMNS(BloatingTable2)) -> Infusion: 1-2g crushed seeds
B11: =OFFSET(BloatingTable2,MATCH('Health Concern'!$B$3,'Digestion & Liver'!$C$2,0)+5, 0,1,COLUMNS(BloatingTable2)) -> Gentian | C11: =OFFSET(BloatingTable2,MATCH('Health Concern'!$B$3,'Digestion & Liver'!$C$2,0)+5, 0,1,COLUMNS(BloatingTable2)) -> Bitter Tonic | D11: =OFFSET(BloatingTable2,MATCH('Health Concern'!$B$3,'Digestion & Liver'!$C$2,0)+5, 0,1,COLUMNS(BloatingTable2)) -> Dyspepsia | E11: =OFFSET(BloatingTable2,MATCH('Health Concern'!$B$3,'Digestion & Liver'!$C$2,0)+5, 0,1,COLUMNS(BloatingTable2)) -> Cold, Bitter | F11: =OFFSET(BloatingTable2,MATCH('Health Concern'!$B$3,'Digestion & Liver'!$C$2,0)+5, 0,1,COLUMNS(BloatingTable2)) -> Avoid with gastric or duodenal ulcers | G11: =OFFSET(BloatingTable2,MATCH('Health Concern'!$B$3,'Digestion & Liver'!$C$2,0)+5, 0,1,COLUMNS(BloatingTable2)) -> Infusion: 2-4g dried root
B12: =OFFSET(BloatingTable2,MATCH('Health Concern'!$B$3,'Digestion & Liver'!$C$2,0)+6, 0,1,COLUMNS(BloatingTable2)) -> Ginger | C12: =OFFSET(BloatingTable2,MATCH('Health Concern'!$B$3,'Digestion & Liver'!$C$2,0)+6, 0,1,COLUMNS(BloatingTable2)) -> Carminative, Diaphoretic | D12: =OFFSET(BloatingTable2,MATCH('Health Concern'!$B$3,'Digestion & Liver'!$C$2,0)+6, 0,1,COLUMNS(BloatingTable2)) -> Dyspepsia | E12: =OFFSET(BloatingTable2,MATCH('Health Concern'!$B$3,'Digestion & Liver'!$C$2,0)+6, 0,1,COLUMNS(BloatingTable2)) -> Hot, Aromatic | F12: =OFFSET(BloatingTable2,MATCH('Health Concern'!$B$3,'Digestion & Liver'!$C$2,0)+6, 0,1,COLUMNS(BloatingTable2)) -> Use with caution in pregnancy | G12: =OFFSET(BloatingTable2,MATCH('Health Concern'!$B$3,'Digestion & Liver'!$C$2,0)+6, 0,1,COLUMNS(BloatingTable2)) -> Infusion: 2-4g dried rhizome
B13: =OFFSET(BloatingTable2,MATCH('Health Concern'!$B$3,'Digestion & Liver'!$C$2,0)+7, 0,1,COLUMNS(BloatingTable2)) -> Globe Artichoke | C13: =OFFSET(BloatingTable2,MATCH('Health Concern'!$B$3,'Digestion & Liver'!$C$2,0)+7, 0,1,COLUMNS(BloatingTable2)) -> Cholagogue, Hepatic | D13: =OFFSET(BloatingTable2,MATCH('Health Concern'!$B$3,'Digestion & Liver'!$C$2,0)+7, 0,1,COLUMNS(BloatingTable2)) -> Dyspepsia | E13: =OFFSET(BloatingTable2,MATCH('Health Concern'!$B$3,'Digestion & Liver'!$C$2,0)+7, 0,1,COLUMNS(BloatingTable2)) -> Cool, Bitter | F13: =OFFSET(BloatingTable2,MATCH('Health Concern'!$B$3,'Digestion & Liver'!$C$2,0)+7, 0,1,COLUMNS(BloatingTable2)) -> Avoid in cases of bile duct obstruction | G13: =OFFSET(BloatingTable2,MATCH('Health Concern'!$B$3,'Digestion & Liver'!$C$2,0)+7, 0,1,COLUMNS(BloatingTable2)) -> Infusion: 2-8g dried leaf
B14: =OFFSET(BloatingTable2,MATCH('Health Concern'!$B$3,'Digestion & Liver'!$C$2,0)+8, 0,1,COLUMNS(BloatingTable2)) -> Greater Celandine | C14: =OFFSET(BloatingTable2,MATCH('Health Concern'!$B$3,'Digestion & Liver'!$C$2,0)+8, 0,1,COLUMNS(BloatingTable2)) -> Cholagogue, Hepatic | D14: =OFFSET(BloatingTable2,MATCH('Health Concern'!$B$3,'Digestion & Liver'!$C$2,0)+8, 0,1,COLUMNS(BloatingTable2)) -> Dyspepsia | E14: =OFFSET(BloatingTable2,MATCH('Health Concern'!$B$3,'Digestion & Liver'!$C$2,0)+8, 0,1,COLUMNS(BloatingTable2)) -> Cold, Bitter | F14: =OFFSET(BloatingTable2,MATCH('Health Concern'!$B$3,'Digestion & Liver'!$C$2,0)+8, 0,1,COLUMNS(BloatingTable2)) -> High doses can be toxic | G14: =OFFSET(BloatingTable2,MATCH('Health Concern'!$B$3,'Digestion & Liver'!$C$2,0)+8, 0,1,COLUMNS(BloatingTable2)) -> Infusion: 2-8g dried herb
B15: =OFFSET(BloatingTable2,MATCH('Health Concern'!$B$3,'Digestion & Liver'!$C$2,0)+9, 0,1,COLUMNS(BloatingTable2)) -> Kawakawa | C15: =OFFSET(BloatingTable2,MATCH('Health Concern'!$B$3,'Digestion & Liver'!$C$2,0)+9, 0,1,COLUMNS(BloatingTable2)) -> Carminative, Diaphoretic | D15: =OFFSET(BloatingTable2,MATCH('Health Concern'!$B$3,'Digestion & Liver'!$C$2,0)+9, 0,1,COLUMNS(BloatingTable2)) -> Diarrhoea, Dyspepsia | E15: =OFFSET(BloatingTable2,MATCH('Health Concern'!$B$3,'Digestion & Liver'!$C$2,0)+9, 0,1,COLUMNS(BloatingTable2)) -> Hot, Aromatic | F15: =OFFSET(BloatingTable2,MATCH('Health Concern'!$B$3,'Digestion & Liver'!$C$2,0)+9, 0,1,COLUMNS(BloatingTable2)) -> Safe for most individuals | G15: =OFFSET(BloatingTable2,MATCH('Health Concern'!$B$3,'Digestion & Liver'!$C$2,0)+9, 0,1,COLUMNS(BloatingTable2)) -> Infusion: 2-6g dried leaves
B16: =OFFSET(BloatingTable2,MATCH('Health Concern'!$B$3,'Digestion & Liver'!$C$2,0)+10, 0,1,COLUMNS(BloatingTable2)) -> Kohekohe | C16: =OFFSET(BloatingTable2,MATCH('Health Concern'!$B$3,'Digestion & Liver'!$C$2,0)+10, 0,1,COLUMNS(BloatingTable2)) -> Astringent | D16: =OFFSET(BloatingTable2,MATCH('Health Concern'!$B$3,'Digestion & Liver'!$C$2,0)+10, 0,1,COLUMNS(BloatingTable2)) -> Diarrhoea | E16: =OFFSET(BloatingTable2,MATCH('Health Concern'!$B$3,'Digestion & Liver'!$C$2,0)+10, 0,1,COLUMNS(BloatingTable2)) -> Cool, Astringent | F16: =OFFSET(BloatingTable2,MATCH('Health Concern'!$B$3,'Digestion & Liver'!$C$2,0)+10, 0,1,COLUMNS(BloatingTable2)) -> Not well-studied for safety | G16: =OFFSET(BloatingTable2,MATCH('Health Concern'!$B$3,'Digestion & Liver'!$C$2,0)+10, 0,1,COLUMNS(BloatingTable2)) -> Infusion: 1-2g dried leaves
B17: =OFFSET(BloatingTable2,MATCH('Health Concern'!$B$3,'Digestion & Liver'!$C$2,0)+11, 0,1,COLUMNS(BloatingTable2)) -> Lemon Balm | C17: =OFFSET(BloatingTable2,MATCH('Health Concern'!$B$3,'Digestion & Liver'!$C$2,0)+11, 0,1,COLUMNS(BloatingTable2)) -> Carminative, Nervine | D17: =OFFSET(BloatingTable2,MATCH('Health Concern'!$B$3,'Digestion & Liver'!$C$2,0)+11, 0,1,COLUMNS(BloatingTable2)) -> Colic (Infants), Dyspepsia | E17: =OFFSET(BloatingTable2,MATCH('Health Concern'!$B$3,'Digestion & Liver'!$C$2,0)+11, 0,1,COLUMNS(BloatingTable2)) -> Cool, Aromatic, Nervine | F17: =OFFSET(BloatingTable2,MATCH('Health Concern'!$B$3,'Digestion & Liver'!$C$2,0)+11, 0,1,COLUMNS(BloatingTable2)) -> Safe for most individuals | G17: =OFFSET(BloatingTable2,MATCH('Health Concern'!$B$3,'Digestion & Liver'!$C$2,0)+11, 0,1,COLUMNS(BloatingTable2)) -> Infusion: 2-4g dried leaves
B18: =OFFSET(BloatingTable2,MATCH('Health Concern'!$B$3,'Digestion & Liver'!$C$2,0)+12, 0,1,COLUMNS(BloatingTable2)) -> Milk Thistle | C18: =OFFSET(BloatingTable2,MATCH('Health Concern'!$B$3,'Digestion & Liver'!$C$2,0)+12, 0,1,COLUMNS(BloatingTable2)) -> Hepatoprotective | D18: =OFFSET(BloatingTable2,MATCH('Health Concern'!$B$3,'Digestion & Liver'!$C$2,0)+12, 0,1,COLUMNS(BloatingTable2)) -> Dyspepsia | E18: =OFFSET(BloatingTable2,MATCH('Health Concern'!$B$3,'Digestion & Liver'!$C$2,0)+12, 0,1,COLUMNS(BloatingTable2)) -> Cool, Bitter | F18: =OFFSET(BloatingTable2,MATCH('Health Concern'!$B$3,'Digestion & Liver'!$C$2,0)+12, 0,1,COLUMNS(BloatingTable2)) -> Avoid in cases of allergy to Asteraceae family | G18: =OFFSET(BloatingTable2,MATCH('Health Concern'!$B$3,'Digestion & Liver'!$C$2,0)+12, 0,1,COLUMNS(BloatingTable2)) -> Infusion: 3-12g dried herb
B19: Peppermint,Mentha x piperita | C19: =OFFSET(BloatingTable2,MATCH('Health Concern'!$B$3,'Digestion & Liver'!$C$2,0)+13, 0,1,COLUMNS(BloatingTable2)) -> Carminative | D19: =OFFSET(BloatingTable2,MATCH('Health Concern'!$B$3,'Digestion & Liver'!$C$2,0)+13, 0,1,COLUMNS(BloatingTable2)) -> Colic (Infants), Dyspepsia | E19: =OFFSET(BloatingTable2,MATCH('Health Concern'!$B$3,'Digestion & Liver'!$C$2,0)+13, 0,1,COLUMNS(BloatingTable2)) -> Cool, Aromatic | F19: =OFFSET(BloatingTable2,MATCH('Health Concern'!$B$3,'Digestion & Liver'!$C$2,0)+13, 0,1,COLUMNS(BloatingTable2)) -> Use with caution in pregnancy | G19: =OFFSET(BloatingTable2,MATCH('Health Concern'!$B$3,'Digestion & Liver'!$C$2,0)+13, 0,1,COLUMNS(BloatingTable2)) -> Infusion: 1-2g dried leaves
B20: =OFFSET(BloatingTable2,MATCH('Health Concern'!$B$3,'Digestion & Liver'!$C$2,0)+14, 0,1,COLUMNS(BloatingTable2)) -> Sage | C20: =OFFSET(BloatingTable2,MATCH('Health Concern'!$B$3,'Digestion & Liver'!$C$2,0)+14, 0,1,COLUMNS(BloatingTable2)) -> Astringent, Antiseptic | D20: =OFFSET(BloatingTable2,MATCH('Health Concern'!$B$3,'Digestion & Liver'!$C$2,0)+14, 0,1,COLUMNS(BloatingTable2)) -> Dyspepsia | E20: =OFFSET(BloatingTable2,MATCH('Health Concern'!$B$3,'Digestion & Liver'!$C$2,0)+14, 0,1,COLUMNS(BloatingTable2)) -> Warm, Aromatic | F20: =OFFSET(BloatingTable2,MATCH('Health Concern'!$B$3,'Digestion & Liver'!$C$2,0)+14, 0,1,COLUMNS(BloatingTable2)) -> Avoid during pregnancy and lactation | G20: =OFFSET(BloatingTable2,MATCH('Health Concern'!$B$3,'Digestion & Liver'!$C$2,0)+14, 0,1,COLUMNS(BloatingTable2)) -> Infusion: 1-4g dried leaves
B23: Select Health Concern: | C23: Colic (Infants):
B25: Aniseed,Pimpinella anisum | C25: Carminative, antispasmodic, digestive relaxant. | D25: Colic in infants | E25: Warming. | F25: Caution with GORD | G25: (1:2) 15-25mLs
B26: Chamomile,Matricaria recutita | C26: Carminative, antispasmodic, digestive relaxant, Anti-inflammatory | D26: Colic, flatulence, IBS | E26: Calming, gentle,soothing. | F26: N/A* | G26: (1:2) 20-60mLs
B27: Fennel,Foeniculum vulgare | C27: Carminative, digestive relaxant | D27: Colic, flatulence | E27: Calming, gentle,soothing | F27: Caution with GORD | G27: 20 -50 mLs (1:2)
B28: Lemon Balm,Melissa officinalis | C28: Carminative, antispasmodic | D28: Colic in infants | E28: Calming, gentle. | F28: N/A* | G28: (1:2) 20-45 mLs
B29: Peppermint,Mentha piperita | C29: Carminative, antispasmodic, | D29: Colic,Digestive & gall bladder dysfunction, Gastritis, IBS, Nausea | E29: Cooling, gentle. | F29: Contraindicated with GORD | G29: (1:2) 15-50 mLs
B30: Vervain,Verbena officinalis | C30: Carminative, digestive relaxant, | D30: Colic in infants | E30: Calming, gentle. | F30: N/A* | G30: (1:2) 20 - 40 mLs
B33: Select Health Concern: | C33: Constipation:
B36: Cascara, Rhamnus purshiana | C36: Laxative | D36: Constipation | E36: Cooling | F36: Not for long term use,Caution during pregnancy and breastfeeding, irritable bowel syndrome or inflammatory gastrointestinal condition | G36: (1:2) 15 - 35mLs
B37: Dandelion Root,Taraxacum officinale | C37: Laxative, hepatic, cholagogue, digestive tonic | D37: Digestive complaints, liver support | E37: Cooling | F37: N/A* | G37: (1:1) 20 - 40mLs
B38: Dandelion whole plant,Taraxacum officinale | C38: Laxative, hepatic, cholagogue, digestive tonic | D38: Digestive complaints, liver support | E38: Cooling | F38: N/A* | G38: (1:2) 25 - 60mLs
B39: Globe Artichoke,Cynara scolymus | C39: Laxative, hepatic, cholagogue, digestive tonic | D39: Digestive dysfunction,IBS, liver support | E39: Cooling,bitter | F39: Avoid in cases of bile duct obstruction | G39: ( 1:2) 15-35 mLS
B40: Harakeke ,Phormium tenax | C40: Laxative, bulk-forming | D40: Constipation, bulk-forming agent | E40: Cooling | F40: Contraindicated in pregnancy,Avoid long term use | G40: (1:2) 15-40mLs
B41: Hoheria, Hoheria populnea | C41: Laxative, bulk-forming | D41: Constipation, bulk-forming agent | E41: Cooling | F41: Digestive tract inflammation:IBD, Constipation, gastritis, GORD | G41: (1:4) 20 - 60mLs
B42: Liquorice,Glycyrrhiza glabra | C42: Laxative, bulk-forming | D42: Digestive complaints, soothing properties,Gastritis, GORD, Peptic Ulcer | E42: Cooling,moistening | F42: Contraindicated with hypertension, hypokalaemia, oedema, congestive heart failure | G42: (1:1) 10-30 mLs
B43: Marshmallow,Althaea officinalis | C43: Laxative, demulcent, | D43: Dyspepsia, Gastritis, GORD, peptic ulcer, IBS, constipation | E43: Cooling,moistening | F43: Take away from medications | G43: (1:5) 20-50 mls
B44: Milk Thistle,Silybum marianum | C44: Choleretic,Antioxidant,Hepatotrophorestorative,Hepatoprotective | D44: Liver support, digestive complaints,Constipation, Digestive dysfunction, Dyspepsia, Gallstones | E44: Cooling,bitter | F44: N/A* | G44: (1:1) 30-60 mLs
B45: Rehmannia,Rehmannia glutinosa | C45: adrenal tonic | D45: General tonification -support overall digestive health and can help regulate bowel movements indirectly | E45: Cooling | F45: Caution during pregnancy | G45: (1:2) 20-60mLs
B46: Rhubarb, Rheum rhabarbarum | C46: Laxative | D46: Constipation | E46: Cooling | F46: For short term use only; Caution during pregnancy, breastfeeding; Take away from mineral supplements | G46: (1:2) 20-50mLs
B47: Slippery Elm, Ulmus rubra | C47: Laxative, demulcent | D47: Digestive complaints, soothing properties | E47: Cooling, moistening
B48: Yellow Dock, Rumex crispus | C48: Laxative, cholagogue, hepatic, digestive tonic | D48: Digestive complaints, liver support | E48: Cooling, bitter | F48: N/A* | G48: (1:2) 15-30 mLs
B51: Select Health Concern: | C51: Diarrhoea:
...

Sheet mens health 
B1: Herbs | C1: Actions | D1: Indications | E1: Energetic Properties | F1: Safety Precautions | G1: Therapeutic Dosage | H1: Ratio
A2: Benign Prostatic Hypertrophy (BPH):
B3: Crataeva,Crataeva nurvala | C3: Bladder tonic,Anti-inflammatory | D3: soothing the bladder and urinary tract,help manage inflammation in the prostate and urinary tract. potentially reducing urinary discomfort often associated with BPH.Tissue Affinity: Urinary system | E3: Cooling,Bitter, Astringent, Downward | F3: N/A* | G3: 30-80ml | H3: 0.043055556
B4: Echinacea blend,E. purpurea & E. angustifolia | C4: immune-modulating,Anti inflammatory,immune enhancer,lymphatic | D4: Supports immune function can contribute to managing inflammation. By reducing inflammation, Echinacea may help alleviate discomfort related to BPH. | E4: Warming,Bitter,rising ,Upward | F4: Caution in individuals with autoimmune conditions | G4: 20-100 ml | H4: 0.043055556
B5: Epilobium,Epilobium parviflorum | C5: astringent, anti-inflammatory, urinary tonic,Antiprostatic | D5: help tonify and tighten tissues, potentially affecting the prostate and urinary structures. Can help reducing inflammation in the prostate, supporting overall prostate health,has affinity Urinary system, Prostate | E5: Cooling,Neutral,Astringent | F5: Contains tannins - take separately from mineral supplements | G5: 20-40 | H5: 0.043055556
B6: Horsetail,Equisetum arvense | C6: diuretic, astringent | D6: Prostatitis, BPH due to it ability to assist in reducing fluid retention, potentially easing urinary symptoms. Its tones and strengthen urinary structures, including the prostate. Has affintiy to the urinary system and bones | E6: Cooling,Drying,Astringent,bitter,downwards | F6: N/A* | G6: 15-45 | H6: 0.043055556
B7: Nettle Root,Urtica dioica | C7: anti-inflammatory, nutritive | D7: contains compounds that can inhibit the enzyme responsible for converting testosterone into dihydrotestosterone (DHT), a hormone implicated in BPH. By reducing DHT levels, nettle root may help prevent prostate tissue growth. ,tissue affinity for the blood and kidneys | E7: Warming,Sweet,uplifting | F7: N/A* | G7: 15-40 | H7: 0.043055556
B8: Saw Palmetto,Serenoa serrulata berry | C8: anti-inflammatory,Antiprostatic | D8: BPH, Prostatitis,Fertility ,nhibiting the enzyme 5-alpha-reductase, which converts testosterone into DHT. By reducing DHT levels, saw palmetto can prevent excessive prostate tissue growth and alleviate urinary symptoms..tissue affinty prostate & reprodcutive system | E8: Warming,bitter,downwards | F8: Caution with warfarin | G8: 15-30 | H8: 0.043055556
A10: Erectile Dysfunction:
B11: Damiana,Turnera diffusa | C11: aphrodisiac,Nervine,tonic | D11: Anxiety, nervous depletion enhance nitric oxide (NO) production, which can promote relaxation of blood vessels and increase blood flow to the genital area. This improved blood circulation can contribute to better erectile functioTissue affinity for nervous system and reproductive system | E11: Warming, stimulating, uplifting, and strengthening. | F11: N/A* | G11: 20-40 | H11: (1:2)
B12: Ginkgo,Ginkgo biloba | C12: circulatory stimulant,Antioxidant | D12: mprove blood flow by enhancing vasodilation and increasing nitric oxide production. This increased blood flow can positively impact erectile function by improving the ability of the blood vessels to supply the genital area with oxygen and nutrients. Tissue Affinity: Circulatory system, Brain | E12: Cooling, drying, stimulating, and tonifying. | F12: N/A* | G12: 30-60 | H12: (3:2)
B13: Korean Ginseng,Panax ginseng | C13: Adaptogen,immunomodulator,Tonic | D13: Male infertility, erectile dysfunction help regulate the hypothalamic-pituitary-adrenal (HPA) axis, reducing stress hormone levels. Improved stress response can alleviate psychological factors contributing to erectile dysfunction. Ginsenosides in Korean Ginseng can also improve nitric oxide synthesis and vasodilation. | E13: Warming, stimulating,sweet upward | F13: Caution during infection and with stimulants | G13: 5-15ml | H13: 0.043055556
B14: Rhodiola,Rhodiola rosea | C14: Adaptogen,Antioxidant | D14: erectile dysfuncion,Adrenal depletion s influence the HPA axis, reducing stress hormone secretion. This can lead to improved mood and mental well-being, positively affecting sexual function.has an effects on neurotransmitters like serotonin and dopamine may also contribute to sexual health. | E14: stimulant, warming, and uplifting. | F14: Take away from mineral supplements,Avoid use with stimulants | G14: : 20-40 | H14: 1.1
B15: Saffron,Crocus sativus | C15: Anti inflammatory,Antioxidant,Aphrodisiac, | D15: Supports sexual health and assists in managing erectile dysfunction By improving mood and reducing stress, may indirectly contribute to improved sexual function. Tissue Affinity: Nervous system, Heart , reproductive system | E15: Warming, uplifting, aromatic, | F15: N/A* | G15: 15-25ml | H15: 1:20,
B16: Schisandra,Schisandra chinensis | C16: Adaptogen,Antioxidant ,Nervine | D16: support the body's stress response systems. It can enhance physical endurance and mental resilience, which can positively influence sexual performance and satisfaction. | E16: astringent, and balancing. | F16: Contraindicated in pregnancy | G16: 25-60 | H16: 1.2
B17: Shatavari,Asparagus racemosa | C17: Adaptogen | D17: Male fertility, Contains phytoestrogens that can help regulate hormonal balance. By impacting testosterone levels and improve reproductive health. By addressing hormonal imbalances, shatavari may support erectile function. | E17: Cooling, nourishing, rejuvenating | F17: Caution in GORD (saponins may aggravate) | G17: 30-60 | H17: 1.2
B18: Withania,Withania somnifera | C18: Adaptogen,immune modulator,antiinflammatory,sedative,relaxant | D18: Male Fertility, Erectile Dysfunction, modulation of stress-related hormone levels, which can enhance resilience to stress and anxiety. This may indirectly contribute to improved sexual performance by reducing psychological barriers. | E18: calming, grounding, and rejuvenating. | F18: N/A* | G18: 10-25ml | H18: 0.12638889
A20: Fertility:
B21: Fenugreek.Foeniculum vulgare | C21: anti oxidant,nutrive ,anti inflammatory , Aphrodisiac,Hypoglycemic | D21: compounds like diosgenin that may influence hormonal balance by modulating insulin sensitivity and androgen levels. Improved insulin sensitivity can positively affect reproductive health, and balanced androgens can support sperm production and overall fertility. | E21: Warming,rejuvenating. | F21: Caution with GORD | G21: 20-50ml | H21: 1.2
B22: Korean Ginseng,Panax ginseng | C22: Adaptogen,immunomodulator,Tonic | D22: regulate the hypothalamic-pituitary-adrenal (HPA) axis, potentially affecting reproductive hormones. can modulate sex hormone levels, which may impact sperm quality and fertility. | E22: Warming, stimulating, | F22: Caution during infection and with stimulants | G22: 5-15mls | H22: 0.043055556
B23: Saw Palmetto,Serenoa serrulata berry | C23: anti-inflammatory,Antiprostatic | D23: BPH, Prostatitis,Fertility inhibition of 5-alpha-reductase can reduce the conversion of testosterone to DHT, promoting hormonal balance. This can be relevant to maintaining prostate health and supporting healthy sperm production. | E23: Warming, | F23: Caution with warfarin | G23: 15-30 | H23: 1.2
B24: Shatavari: | C24: Adaptogen | D24: Male fertilityassists in managing erectile dysfunction.potential effects on hormonal balance may contribute to sperm production and quality. | E24: Cooling, nourishing, rejuvenating | F24: Caution in GORD (saponins may aggravate) | G24: 30-60 | H24: 1.2
B25: Withania: | C25: Adaptogen,immune modulator,antiinflammatory,sedative,relaxant | D25: it can influence stress-related hormones and may improve stress resilience. Stress reduction can positively impact reproductive hormones, including testosterone, which is crucial for sperm production and male fertility. | E25: calming, grounding, and rejuvenating. | F25: N/A* | G25: 10-25ml | H25: 3.2
A27: Prostatitis:
B28: Andrographis,Andrographis paniculata | C28: anti inflmmatory,immune enhancing,choleretic,anthelmintic | D28: Assists in managing prostate inflammation and supports prostatitis management | E28: Cooling, bitter, | F28: Contraindicated in 1st trimester of pregnancy | G28: 20-40ml | H28: 1.2
B29: Bearberry,Arctostaphylos uva-ursi | C29: Anti inflammatory,astringent,urinary antiseptic | D29: cystitis,kidney stones,prostatitiscontains arbutin, which is metabolized into hydroquinone, a compound with antimicrobial properties. It may help combat bacterial infections that contribute to prostatitis. | E29: Cooling, astringent | F29: Contraindicated in pregnancy & breastfeeding,kidney disease and children under 12 years | G29: 30-60 | H29: 1.2
B30: Buchu,Barosma betulina | C30: diuretic,urinary antiseptic | D30: Supports urinary tract health and assists in managing prostatitis, cystitis due to reducing inflammation and infection associated with prostatitis. | E30: Warming | F30: N/A* | G30: 15-30 | H30: 1.2
B31: Cornsilk.Zea mays | C31: diuretic, Demulcent,Antilithic | D31: help flush the urinary tract and potentially alleviate urinary discomfort associated with prostatitis. Its soothing properties may also contribute to symptom relief. | E31: Cooling, soothing | F31: N/A* | G31: 30-80 | H31: 1.2
B32: Couchgrass,Agropyron repens | C32: Demulcent,diuretic | D32: provide soothing effects to the urinary tract. Its aids in flushing the urinary system and potentially alleviating prostatitis symptoms. | E32: Cooling,soothing | F32: N/A* | G32: 40-80 | H32: 1.2
B33: Echinacea blend,E. purpurea & E. angustifolia | C33: immune-modulating,Anti inflammatory,immune enhancer,lymphatic | D33: enhance the body's defense mechanisms against infections associated with prostatitis. Its reduces inflamation which can contribute to symptom relief. | E33: Cooling, | F33: Caution in individuals with autoimmune conditions | G33: 20-100 ml | H33: 1.2
B34: Gravelroot,Eupatorium purpureum | C34: Antilithic,Diuretic | D34: Assists in reducing urinary discomfort and supports prostatitis management, kindey stones due to its ability to flush out the urinary tract, potentially reducing discomfort caused by prostatitis | E34: Cooling, | F34: N/A* | G34: 15-30 | H34: 1.2
B35: Horsetail,Equisetum arvense | C35: diuretic, astringent | D35: Supports urinary tract health and assists in managing prostatitis, assists in managing BPH. It promoties the elimination of toxins and pathogens. It also helps with inflamation which may contribute to symptom relief. | E35: Cooling, | F35: N/A* | G35: 15-45 | H35: 1.2
B36: Juniper,Juniperus communis | C36: urinary antiseptic,diuretic,antinflmmatory | D36: helping to combat infections contributing to prostatitis. Its also aid in flushing the urinary tract. | E36: Warming | F36: Contraindicated in pregnancy | G36: 10-20ml | H36: 1.2
B37: Nettle Root,Urtica dioica | C37: anti-inflammatory, nutritive | D37: Inhibit enzymes that contribute to the growth of prostate cells, potentially impacting prostate enlargement. | E37: Warming,sweet,upward | F37: N/A* | G37: 15-40 | H37: 1.2
B38: Saw Palmetto,Serenoa serrulata berry | C38: anti-inflammatory,Antiprostatic | D38: inhibition of 5-alpha-reductase and anti-inflammatory effects may help manage symptoms of prostatitis by reducing inflammation and potentially impacting prostate growth. | E38: Warming.downard, bitter | F38: caution with warfarin | G38: 15-30 | H38: 1.2

Sheet Haematology
B1: Herbs | C1: Actions | D1: Indications | E1: Energetic Properties | F1: Safety Precautions | G1: Therapeutic Dosage | H1: Ratio
A2: Anaemia: | B2: Codonopsis,Codonopsis pilosula | C2: tonic | D2: Fatigue,Anemia -helps the body adapt to stressors. It can improve energy levels by supporting adrenal function, enhancing oxygen utilization, and increasing the body's overall resilience to fatigue.upports red blood cell production | E2: strengthening, Sweet, slightly bitter,Upward-moving, nourishing | F2: N/a* | G2: 30-60 | H2: 1.2
B3: Dong Quai,Angelica sinensis | C3: anti anaemic,Antiplatelet | D3: ,Anaemia,Endometriosis,Menstrual irrgeularity, - ontains iron and vitamins that help increase hemoglobin levels, improving oxygen transport and addressing anemia. It also supports blood circulation, enhancing the delivery of nutrients and oxygen to tissues. | E3: Harmonizing, invigorating,Bitter, pungent, sweet,Blood-moving, tonifying | F3: Contraindicated during pregnancy,Caution with heavy menstruation | G3: 30-60 | H3: 1.2
B4: Nettle Leaf:Urtica dioica | C4: Nutritive | D4: ich in iron and other nutrients essential for red blood cell production. Its high iron content supports hemoglobin synthesis, helping to alleviate anemia. It also enhances iron absorption and prevents iron deficiency. | E4: Restorative, nourishing,Salty, slightly bitter, Downward-moving, cleansing | F4: N/a* | G4: 15-40 | H4: 1.2
